# Go 错误

Go 没有像 Java 和 .NET 那样的 try/catch 异常机制：不能执行抛异常操作。但是有一套 defer-panic-and-recover 机制

Go 的设计者觉得 try/catch 机制的使用太泛滥了，而且从底层向更高的层级抛异常太耗费资源。他们给 Go 设计的机制也可以 “捕捉” 异常，但是更轻量，并且只应该作为（处理错误的）最后的手段。

Go 是怎么处理普通错误的呢？通过在函数和方法中返回错误对象作为它们的唯一或最后一个返回值 —— 如果返回 nil，则没有错误发生 —— 并且主调（calling）函数总是应该检查收到的错误

处理错误并且在函数发生错误的地方给用户返回错误信息：照这样处理就算真的出了问题，你的程序也能继续运行并且通知给用户。panic and recover 是用来处理真正的异常（无法预测的错误）而不是普通的错误。

库函数通常必须返回某种错误提示给主调（calling）函数。

Go有一个预先定义的error接口类型

```go
type error interface {
  Error() string
}

```

任何时候当你需要一个新的错误类型，都可以用 errors（必须先 import）包的 errors.New 函数接收合适的错误信息来创建

```go
err := errors.New("错误~")

```

在大部分情况下自定义错误结构类型很有意义的，可以包含除了（低层级的）错误信息以外的其它有用信息

```go
type PathError struct {
  Op string
  Path string
  Err error
}

func (e *PathError) String() string {
  return e.Op + " " + e.Path + ": " + e.Err.Error()
}

```

如果有不同错误条件可能发生，那么对实际的错误使用类型断言或类型判断（type-switch）是很有用的，并且可以根据错误场景做一些补救和恢复操作

```go
//  err != nil
if e, ok := err.(*os.PathError); ok {
    // remedy situation
}

```

或:

```go
switch err := err.(type) {
    case ParseError:
        PrintParseError(err)
    case PathError:
        PrintPathError(err)
    ...
    default:
        fmt.Printf("Not a special error, just %s\n", err)
}

```

通常你想要返回包含错误参数的更有信息量的字符串，例如：可以用 fmt.Errorf() 来实现：它和 fmt.Printf () 完全一样，接收有一个或多个格式占位符的格式化字符串和相应数量的占位变量。和打印信息不同的是它用信息生成错误对象。

```go
func Sqrt(f float64) (float64, error) {
    if f < 0 {
        //return 0, errors.New ("math - square root of negative number")
        return 0, fmt.Errorf("math: square root of negative number %g", f)
    }
   // implementation of Sqrt
}

```

### 运行时异常和panic

当发生像数组下标越界或类型断言失败这样的运行错误时，Go 运行时会触发运行时 **`panic`**，伴随着程序的崩溃抛出一个`runtime.Error`接口类型的值。这个错误值有个 `RuntimeError()` 方法用于区别普通错误

`panic` 可以直接从代码初始化：当错误条件（我们所测试的代码）很严苛且不可恢复，程序不能继续运行时，可以使用 `panic` 函数产生一个中止程序的运行时错误。`panic` 接收一个做任意类型的参数，通常是字符串，在程序死亡时被打印出来。Go 运行时负责中止程序并给出调试信息。

```go
package main

import "fmt"

func main() {
    fmt.Println("Starting the program")
    panic("A severe error occurred: stopping the program!")
    fmt.Println("Ending the program")
}

```

在多层嵌套的函数调用中调用 panic，可以马上中止当前函数的执行，所有的 defer 语句都会保证执行并把控制权交还给接收到 panic 的函数调用者。这样向上冒泡直到最顶层，并执行（每层的） defer，在栈顶处程序崩溃，并在命令行中用传给 panic 的值报告错误情况：这个终止过程就是 panicking

recover内建函数被用于从 panic 或 错误场景中恢复：让程序可以从 panicking 重新获得控制权，停止终止过程进而恢复正常执行

`recover` 只能在 defer 修饰的函数中使用：用于取得 `panic` 调用中传递过来的错误值，如果是正常执行，调用 `recover` 会返回 nil，且没有其它效果。

总结：panic 会导致栈被展开直到 defer 修饰的 recover () 被调用或者程序中止。

```go
func protect(g func()) {
    defer func() {
        log.Println("done")
        // Println executes normally even if there is a panic
        if err := recover(); err != nil {
        log.Printf("run time panic: %v", err)
        }
    }()
    log.Println("start")
    g() //   possible runtime-error
}

```